Workbook

Sheet Sheet1
A1: Project_ID | B1: Environment | C1: Account_ID | D1: Department | E1: Application | F1: Number_of_Servers | G1: Usage_Cost | H1: Incident_Tickets_Opened | I1: Incident_Tickets_Closed | J1: Avg_Resolution_Time_Hours | K1: Region | L1: Region_Clean | M1: Cloud_Provider | N1: Project_Start_Date | O1: Project_End_Date | P1: Compliance_Flag | Q1: SLA_Breach_Count | R1: Security_Alerts | S1: Resource_Utilization_Percent | T1: Reserved_Instance_Usage | U1: Tagging_Completeness | V1: Budget_Allocated | W1: Budget_Consumed | X1: Budget_Utilization | Y1: Over_Budget_Flag | Z1: Cost_Anomaly_Flag | AA1: Project_Name | AB1: Date
A2: PRJ100000 | F2: 964 | G2: 1756.5 | H2: 76 | I2: 76 | J2: 5.29 | K2: Europe-West | L2: =IF(OR(K2="Europe-West",K2="EU_West",K2="eu-west"),"EU-West", IF(OR(K2="US_East",K2="us-east",K2="US-East"),"US-East","Other")) -> EU-West | Q2: 0 | R2: 13 | S2: 60.85 | T2: 59.75 | U2: 92.89 | V2: 1782.4906 | W2: 1934.0018 | X2: =W2/V2 -> 1.0849997 | Y2: =IF(X2>1,"Over Budget","OK") -> Over Budget | AA2: CloudProject_0 | AB2: 45687.218
A3: PRJ100001 | F3: 962 | G3: 1719.6 | H3: 26 | I3: 30 | J3: 25.1 | K3: US_East | L3: =IF(OR(K3="Europe-West",K3="EU_West",K3="eu-west"),"EU-West", IF(OR(K3="US_East",K3="us-east",K3="US-East"),"US-East","Other")) -> US-East | Q3: 30 | R3: 33 | S3: 67.37 | T3: 68.63 | U3: 99 | V3: 2047.1372 | W3: 1566.6114 | X3: =W3/V3 -> 0.76526937 | Y3: =IF(X3>1,"Over Budget","OK") -> OK | AA3: CloudProject_1 | AB3: 45583.887
A4: PRJ100002 | F4: 870 | G4: 1815.63 | H4: 74 | I4: 71 | J4: 13.21 | K4: us-east | L4: =IF(OR(K4="Europe-West",K4="EU_West",K4="eu-west"),"EU-West", IF(OR(K4="US_East",K4="us-east",K4="US-East"),"US-East","Other")) -> US-East | Q4: 20 | R4: 1 | S4: 93 | T4: 60.42 | U4: 95.91 | V4: 2185.5958 | W4: 1719.7018 | X4: =W4/V4 -> 0.78683431 | Y4: =IF(X4>1,"Over Budget","OK") -> OK | AA4: CloudProject_2 | AB4: 45585.36
A5: PRJ100003 | F5: 136 | G5: 1686.22 | H5: 95 | I5: 93 | J5: 8.95 | K5: us-east | L5: =IF(OR(K5="Europe-West",K5="EU_West",K5="eu-west"),"EU-West", IF(OR(K5="US_East",K5="us-east",K5="US-East"),"US-East","Other")) -> US-East | Q5: 20 | R5: 19 | S5: 76.23 | T5: 58.59 | U5: 86.56 | V5: 2095.2212 | W5: 1764.7533 | X5: =W5/V5 -> 0.8422754 | Y5: =IF(X5>1,"Over Budget","OK") -> OK | AA5: CloudProject_3 | AB5: 45171.002
A6: PRJ100004 | F6: 255 | G6: 2375.35 | H6: 66 | I6: 63 | J6: 24.27 | K6: US-East | L6: =IF(OR(K6="Europe-West",K6="EU_West",K6="eu-west"),"EU-West", IF(OR(K6="US_East",K6="us-east",K6="US-East"),"US-East","Other")) -> US-East | Q6: 10 | R6: 41 | S6: 48.28 | T6: 59.47 | U6: 90.57 | V6: 3169.9177 | W6: 2295.6711 | X6: =W6/V6 -> 0.72420527 | Y6: =IF(X6>1,"Over Budget","OK") -> OK | AA6: CloudProject_4 | AB6: 45081.11
A7: PRJ100005 | F7: 833 | G7: 1734.76 | H7: 48 | I7: 45 | J7: 11.96 | K7: Europe-West | L7: =IF(OR(K7="Europe-West",K7="EU_West",K7="eu-west"),"EU-West", IF(OR(K7="US_East",K7="us-east",K7="US-East"),"US-East","Other")) -> EU-West | Q7: 0 | R7: 15 | S7: 42.53 | T7: 38.82 | U7: 97.61 | V7: 2055.4189 | W7: 1736.8723 | X7: =W7/V7 -> 0.84502108 | Y7: =IF(X7>1,"Over Budget","OK") -> OK | AA7: CloudProject_5 | AB7: 45341.224
A8: PRJ100006 | F8: 243 | G8: 1419.23 | H8: 1 | I8: 2 | J8: 32.31 | K8: Europe-West | L8: =IF(OR(K8="Europe-West",K8="EU_West",K8="eu-west"),"EU-West", IF(OR(K8="US_East",K8="us-east",K8="US-East"),"US-East","Other")) -> EU-West | Q8: 30 | R8: 2 | S8: 71.41 | T8: 58.41 | U8: 92.62 | V8: 1570.4753 | W8: 1531.7286 | X8: =W8/V8 -> 0.97532806 | Y8: =IF(X8>1,"Over Budget","OK") -> OK | AA8: CloudProject_6 | AB8: 45236.442
A9: PRJ100007 | F9: 676 | G9: 1565.75 | H9: 93 | I9: 92 | J9: 21.25 | K9: us-east | L9: =IF(OR(K9="Europe-West",K9="EU_West",K9="eu-west"),"EU-West", IF(OR(K9="US_East",K9="us-east",K9="US-East"),"US-East","Other")) -> US-East | Q9: 0 | R9: 45 | S9: 100 | T9: 49.35 | U9: 95.05 | V9: 2258.4948 | W9: 1545.2392 | X9: =W9/V9 -> 0.68418984 | Y9: =IF(X9>1,"Over Budget","OK") -> OK | AA9: CloudProject_7 | AB9: 45293.117
A10: PRJ100008 | F10: 594 | G10: 1841.7 | H10: 59 | I10: 58 | J10: 18.38 | K10: us-east | L10: =IF(OR(K10="Europe-West",K10="EU_West",K10="eu-west"),"EU-West", IF(OR(K10="US_East",K10="us-east",K10="US-East"),"US-East","Other")) -> US-East | Q10: 0 | R10: 29 | S10: 90.34 | T10: 57.93 | U10: 93.26 | V10: 2745.0894 | W10: 1614.0436 | X10: =W10/V10 -> 0.58797488 | Y10: =IF(X10>1,"Over Budget","OK") -> OK | AA10: CloudProject_8 | AB10: 45815.164
A11: PRJ100009 | F11: 940 | G11: 1895.44 | H11: 65 | I11: 61 | J11: 13.43 | K11: Europe-West | L11: =IF(OR(K11="Europe-West",K11="EU_West",K11="eu-west"),"EU-West", IF(OR(K11="US_East",K11="us-east",K11="US-East"),"US-East","Other")) -> EU-West | Q11: 0 | R11: 22 | T11: 59.76 | U11: 90.38 | V11: 1914.4083 | W11: 1911.0387 | X11: =W11/V11 -> 0.99823984 | Y11: =IF(X11>1,"Over Budget","OK") -> OK | AA11: CloudProject_9 | AB11: 44984.656
A12: PRJ100010 | F12: 448 | G12: 2405.74 | H12: 58 | I12: 55 | J12: 21.72 | K12: us-east | L12: =IF(OR(K12="Europe-West",K12="EU_West",K12="eu-west"),"EU-West", IF(OR(K12="US_East",K12="us-east",K12="US-East"),"US-East","Other")) -> US-East | Q12: 0 | R12: 38 | S12: 81.78 | T12: 64.59 | U12: 89.65 | V12: 3063.0686 | W12: 2267.2831 | X12: =W12/V12 -> 0.74019993 | Y12: =IF(X12>1,"Over Budget","OK") -> OK | AA12: CloudProject_10 | AB12: 45088.497
A13: PRJ100011 | F13: 146 | G13: 1876.17 | H13: 92 | I13: 89 | J13: 7.27 | K13: EU_West | L13: =IF(OR(K13="Europe-West",K13="EU_West",K13="eu-west"),"EU-West", IF(OR(K13="US_East",K13="us-east",K13="US-East"),"US-East","Other")) -> EU-West | Q13: 0 | R13: 22 | S13: 82.91 | T13: 80.14 | U13: 83.95 | V13: 2196.7159 | W13: 1719.1227 | X13: =W13/V13 -> 0.78258766 | Y13: =IF(X13>1,"Over Budget","OK") -> OK | AA13: CloudProject_11 | AB13: 45918.354
A14: PRJ100012 | F14: 795 | G14: 2047.55 | H14: 59 | I14: 59 | J14: 1 | K14: us-east | L14: =IF(OR(K14="Europe-West",K14="EU_West",K14="eu-west"),"EU-West", IF(OR(K14="US_East",K14="us-east",K14="US-East"),"US-East","Other")) -> US-East | Q14: 0 | R14: 2 | S14: 45.47 | T14: 73.45 | U14: 86.17 | V14: 2331.125 | W14: 1906.7675 | X14: =W14/V14 -> 0.8179602 | Y14: =IF(X14>1,"Over Budget","OK") -> OK | AA14: CloudProject_12 | AB14: 44979.331
A15: PRJ100013 | F15: 565 | G15: 1781.63 | H15: 21 | I15: 24 | J15: 7.57 | K15: US-East | L15: =IF(OR(K15="Europe-West",K15="EU_West",K15="eu-west"),"EU-West", IF(OR(K15="US_East",K15="us-east",K15="US-East"),"US-East","Other")) -> US-East | Q15: 10 | R15: 12 | S15: 73.12 | T15: 59.89 | V15: 2080.6823 | W15: 1738.1598 | X15: =W15/V15 -> 0.83537973 | Y15: =IF(X15>1,"Over Budget","OK") -> OK | AA15: CloudProject_13 | AB15: 44965.713
A16: PRJ100014 | F16: 768 | H16: 88 | I16: 86 | J16: 29.1 | K16: eu-west | L16: =IF(OR(K16="Europe-West",K16="EU_West",K16="eu-west"),"EU-West", IF(OR(K16="US_East",K16="us-east",K16="US-East"),"US-East","Other")) -> EU-West | Q16: 20 | R16: 45 | S16: 89.7 | T16: 65.59 | U16: 88.24 | V16: 2733.4815 | W16: 2392.0786 | X16: =W16/V16 -> 0.87510326 | Y16: =IF(X16>1,"Over Budget","OK") -> OK | AA16: CloudProject_14 | AB16: 45816.971
A17: PRJ100015 | F17: 158 | G17: 1395.58 | H17: 45 | I17: 50 | J17: 12.61 | K17: us-east | L17: =IF(OR(K17="Europe-West",K17="EU_West",K17="eu-west"),"EU-West", IF(OR(K17="US_East",K17="us-east",K17="US-East"),"US-East","Other")) -> US-East | Q17: 30 | R17: 39 | S17: 100 | T17: 56 | U17: 90.5 | V17: 1528.6597 | W17: 1526.2382 | X17: =W17/V17 -> 0.99841589 | Y17: =IF(X17>1,"Over Budget","OK") -> OK | AA17: CloudProject_15 | AB17: 45278.268
A18: PRJ100016 | F18: 65 | H18: 52 | I18: 48 | J18: 8.52 | K18: EU_West | L18: =IF(OR(K18="Europe-West",K18="EU_West",K18="eu-west"),"EU-West", IF(OR(K18="US_East",K18="us-east",K18="US-East"),"US-East","Other")) -> EU-West | Q18: 0 | R18: 28 | S18: 77.59 | T18: 61.92 | U18: 89.46 | V18: 3039.6867 | W18: 2227.2332 | X18: =W18/V18 -> 0.73271803 | Y18: =IF(X18>1,"Over Budget","OK") -> OK | AA18: CloudProject_16 | AB18: 45423.066
A19: PRJ100017 | F19: 697 | G19: 1829.27 | H19: 18 | I19: 20 | J19: 19.29 | K19: US-East | L19: =IF(OR(K19="Europe-West",K19="EU_West",K19="eu-west"),"EU-West", IF(OR(K19="US_East",K19="us-east",K19="US-East"),"US-East","Other")) -> US-East | Q19: 0 | R19: 22 | S19: 49.62 | T19: 62.14 | U19: 91.08 | V19: 2255.5947 | W19: 1808.2409 | X19: =W19/V19 -> 0.80166924 | Y19: =IF(X19>1,"Over Budget","OK") -> OK | AA19: CloudProject_17 | AB19: 45826.9
A20: PRJ100018 | F20: 365 | G20: 2436.87 | H20: 48 | I20: 44 | J20: 37.8 | K20: EU_West | L20: =IF(OR(K20="Europe-West",K20="EU_West",K20="eu-west"),"EU-West", IF(OR(K20="US_East",K20="us-east",K20="US-East"),"US-East","Other")) -> EU-West | Q20: 0 | R20: 39 | S20: 78.57 | T20: 50.2 | U20: 93.32 | V20: 2833.5642 | W20: 1951.2797 | X20: =W20/V20 -> 0.68863085 | Y20: =IF(X20>1,"Over Budget","OK") -> OK | AA20: CloudProject_18 | AB20: 45647.494
A21: PRJ100019 | F21: 266 | G21: 2484.81 | H21: 79 | I21: 83 | J21: 28.74 | K21: eu-west | L21: =IF(OR(K21="Europe-West",K21="EU_West",K21="eu-west"),"EU-West", IF(OR(K21="US_East",K21="us-east",K21="US-East"),"US-East","Other")) -> EU-West | Q21: 30 | R21: 16 | S21: 78.32 | T21: 55.39 | U21: 87.92 | V21: 3435.91 | W21: 2326.3295 | X21: =W21/V21 -> 0.67706359 | Y21: =IF(X21>1,"Over Budget","OK") -> OK | AA21: CloudProject_19 | AB21: 45693.317
A22: PRJ100020 | F22: 932 | G22: 2142.36 | H22: 16 | I22: 17 | J22: 13.6 | K22: US_East | L22: =IF(OR(K22="Europe-West",K22="EU_West",K22="eu-west"),"EU-West", IF(OR(K22="US_East",K22="us-east",K22="US-East"),"US-East","Other")) -> US-East | Q22: 10 | R22: 20 | S22: 83.04 | T22: 43.03 | U22: 93.69 | V22: 2159.8702 | W22: 2410.748 | X22: =W22/V22 -> 1.1161541 | Y22: =IF(X22>1,"Over Budget","OK") -> Over Budget | AA22: CloudProject_20 | AB22: 45468.576
A23: PRJ100021 | F23: 822 | G23: 1784.14 | H23: 26 | I23: 25 | J23: 13.45 | K23: eu-west | L23: =IF(OR(K23="Europe-West",K23="EU_West",K23="eu-west"),"EU-West", IF(OR(K23="US_East",K23="us-east",K23="US-East"),"US-East","Other")) -> EU-West | Q23: 10 | R23: 28 | S23: 76.1 | T23: 58.25 | U23: 95.69 | V23: 2169.383 | W23: 1704.3325 | X23: =W23/V23 -> 0.78563007 | Y23: =IF(X23>1,"Over Budget","OK") -> OK | AA23: CloudProject_21 | AB23: 45175.826
A24: PRJ100022 | F24: 72 | G24: 1805.56 | H24: 18 | I24: 23 | J24: 13.63 | K24: US-East | L24: =IF(OR(K24="Europe-West",K24="EU_West",K24="eu-west"),"EU-West", IF(OR(K24="US_East",K24="us-east",K24="US-East"),"US-East","Other")) -> US-East | Q24: 0 | R24: 36 | S24: 97.9 | T24: 59.64 | U24: 92.08 | V24: 2126.321 | W24: 1851.6517 | X24: =W24/V24 -> 0.87082417 | Y24: =IF(X24>1,"Over Budget","OK") -> OK | AA24: CloudProject_22 | AB24: 45624.005
A25: PRJ100023 | F25: 835 | G25: 1570 | H25: 29 | I25: 31 | J25: 12.72 | K25: eu-west | L25: =IF(OR(K25="Europe-West",K25="EU_West",K25="eu-west"),"EU-West", IF(OR(K25="US_East",K25="us-east",K25="US-East"),"US-East","Other")) -> EU-West | Q25: 0 | R25: 4 | S25: 72.85 | T25: 59.27 | U25: 87.28 | V25: 1840.3816 | W25: 1388.2629 | X25: =W25/V25 -> 0.75433426 | Y25: =IF(X25>1,"Over Budget","OK") -> OK | AA25: CloudProject_23 | AB25: 45850.119
A26: PRJ100024 | F26: 945 | G26: 1858.43 | H26: 77 | I26: 80 | J26: 24.35 | K26: us-east | L26: =IF(OR(K26="Europe-West",K26="EU_West",K26="eu-west"),"EU-West", IF(OR(K26="US_East",K26="us-east",K26="US-East"),"US-East","Other")) -> US-East | Q26: 0 | R26: 20 | S26: 70.89 | T26: 49.99 | U26: 94.73 | V26: 2171.6418 | W26: 2167.567 | X26: =W26/V26 -> 0.99812365 | Y26: =IF(X26>1,"Over Budget","OK") -> OK | AA26: CloudProject_24 | AB26: 45122.161
A27: PRJ100025 | F27: 72 | G27: 1459.28 | H27: 45 | I27: 47 | J27: 17.31 | K27: us-east | L27: =IF(OR(K27="Europe-West",K27="EU_West",K27="eu-west"),"EU-West", IF(OR(K27="US_East",K27="us-east",K27="US-East"),"US-East","Other")) -> US-East | Q27: 30 | R27: 1 | S27: 66.07 | T27: 59.2 | U27: 92.41 | V27: 1482.0968 | W27: 1706.2897 | X27: =W27/V27 -> 1.1512673 | Y27: =IF(X27>1,"Over Budget","OK") -> Over Budget | AA27: CloudProject_25 | AB27: 45532.162
A28: PRJ100026 | F28: 815 | G28: 1850.97 | H28: 63 | I28: 63 | J28: 11.09 | K28: Europe-West | L28: =IF(OR(K28="Europe-West",K28="EU_West",K28="eu-west"),"EU-West", IF(OR(K28="US_East",K28="us-east",K28="US-East"),"US-East","Other")) -> EU-West | Q28: 0 | R28: 22 | S28: 71.46 | T28: 61.62 | U28: 93.09 | V28: 1991.7514 | W28: 1588.9248 | X28: =W28/V28 -> 0.79775253 | Y28: =IF(X28>1,"Over Budget","OK") -> OK | AA28: CloudProject_26 | AB28: 45297.938
A29: PRJ100027 | F29: 38 | G29: 2406.42 | H29: 31 | I29: 27 | J29: 9.31 | K29: EU_West | L29: =IF(OR(K29="Europe-West",K29="EU_West",K29="eu-west"),"EU-West", IF(OR(K29="US_East",K29="us-east",K29="US-East"),"US-East","Other")) -> EU-West | Q29: 40 | R29: 10 | S29: 74.19 | T29: 64.62 | U29: 97.68 | V29: 2577.1376 | W29: 2622.1882 | X29: =W29/V29 -> 1.0174809 | Y29: =IF(X29>1,"Over Budget","OK") -> Over Budget | AA29: CloudProject_27 | AB29: 45634.598
A30: PRJ100028 | F30: 561 | G30: 1750.54 | H30: 52 | I30: 52 | J30: 38.41 | K30: US-East | L30: =IF(OR(K30="Europe-West",K30="EU_West",K30="eu-west"),"EU-West", IF(OR(K30="US_East",K30="us-east",K30="US-East"),"US-East","Other")) -> US-East | Q30: 40 | R30: 14 | S30: 71.84 | T30: 62.68 | U30: 93.55 | V30: 2615.8411 | W30: 1453.1152 | X30: =W30/V30 -> 0.55550591 | Y30: =IF(X30>1,"Over Budget","OK") -> OK | AA30: CloudProject_28 | AB30: 45646.849
... A38: PRJ100036 | F38: 150 | G38: 1775.5 | H38: 78 | I38: 80 | J38: 12.46 | K38: eu-west | L38: =IF(OR(K38="Europe-West",K38="EU_West",K38="eu-west"),"EU-West", IF(OR(K38="US_East",K38="us-east",K38="US-East"),"US-East","Other")) -> EU-West | Q38: 10 | R38: 43 | S38: 70.74 | T38: 67.22 | U38: 90.44 | V38: 1897.8346 | W38: 1846.0766 | X38: =W38/V38 -> 0.97272784 | Y38: =IF(X38>1,"Over Budget","OK") -> OK | AA38: CloudProject_36 | AB38: 45492.978
A39: PRJ100037 | F39: 935 | G39: 1452.65 | H39: 31 | I39: 30 | J39: 21.03 | K39: US_East | L39: =IF(OR(K39="Europe-West",K39="EU_West",K39="eu-west"),"EU-West", IF(OR(K39="US_East",K39="us-east",K39="US-East"),"US-East","Other")) -> US-East | Q39: 0 | R39: 5 | T39: 69.32 | U39: 96.01 | V39: 1940.1493 | W39: 1297.4478 | X39: =W39/V39 -> 0.6687361 | Y39: =IF(X39>1,"Over Budget","OK") -> OK | AA39: CloudProject_37 | AB39: 45160.725
A40: PRJ100038 | F40: 516 | G40: 1665.36 | H40: 90 | I40: 94 | J40: 6.01 | K40: eu-west | L40: =IF(OR(K40="Europe-West",K40="EU_West",K40="eu-west"),"EU-West", IF(OR(K40="US_East",K40="us-east",K40="US-East"),"US-East","Other")) -> EU-West | Q40: 10 | R40: 15 | S40: 78.65 | T40: 51.52 | U40: 93.31 | V40: 2480.7007 | W40: 1508.1606 | X40: =W40/V40 -> 0.6079575 | Y40: =IF(X40>1,"Over Budget","OK") -> OK | AA40: CloudProject_38 | AB40: 44966.182
A41: PRJ100039 | F41: 570 | G41: 2461.62 | H41: 51 | I41: 55 | J41: 16.99 | K41: US-East | L41: =IF(OR(K41="Europe-West",K41="EU_West",K41="eu-west"),"EU-West", IF(OR(K41="US_East",K41="us-east",K41="US-East"),"US-East","Other")) -> US-East | Q41: 0 | R41: 1 | S41: 74.87 | T41: 79.25 | U41: 83.55 | V41: 3116.3773 | W41: 2830.0461 | X41: =W41/V41 -> 0.90812049 | Y41: =IF(X41>1,"Over Budget","OK") -> OK | AA41: CloudProject_39 | AB41: 45444.807
A42: PRJ100040 | F42: 508 | G42: 2411.55 | H42: 0 | I42: -1 | J42: 30.68 | K42: us-east | L42: =IF(OR(K42="Europe-West",K42="EU_West",K42="eu-west"),"EU-West", IF(OR(K42="US_East",K42="us-east",K42="US-East"),"US-East","Other")) -> US-East | Q42: 0 | R42: 31 | S42: 70.05 | T42: 52.93 | U42: 85.92 | V42: 2669.6879 | W42: 2039.5209 | X42: =W42/V42 -> 0.7639548 | Y42: =IF(X42>1,"Over Budget","OK") -> OK | AA42: CloudProject_40 | AB42: 45720.687
A43: PRJ100041 | F43: 636 | G43: 1315.45 | H43: 13 | I43: 10 | J43: 28.2 | K43: EU_West | L43: =IF(OR(K43="Europe-West",K43="EU_West",K43="eu-west"),"EU-West", IF(OR(K43="US_East",K43="us-east",K43="US-East"),"US-East","Other")) -> EU-West | Q43: 30 | R43: 42 | S43: 74.29 | T43: 57.73 | U43: 91.43 | V43: 1726.7148 | W43: 1368.8521 | X43: =W43/V43 -> 0.7927494 | Y43: =IF(X43>1,"Over Budget","OK") -> OK | AA43: CloudProject_41 | AB43: 45121.969
A44: PRJ100042 | F44: 511 | G44: 3425.38 | H44: 2 | I44: 5 | J44: 14.43 | K44: US_East | L44: =IF(OR(K44="Europe-West",K44="EU_West",K44="eu-west"),"EU-West", IF(OR(K44="US_East",K44="us-east",K44="US-East"),"US-East","Other")) -> US-East | Q44: 20 | R44: 46 | S44: 74.32 | T44: 71.9 | U44: 90.8 | V44: 4303.8695 | W44: 3290.0851 | X44: =W44/V44 -> 0.76444814 | Y44: =IF(X44>1,"Over Budget","OK") -> OK | AA44: CloudProject_42 | AB44: 45530.673
A45: PRJ100043 | F45: 750 | G45: 2615.39 | H45: 29 | I45: 25 | J45: 7.79 | K45: Europe-West | L45: =IF(OR(K45="Europe-West",K45="EU_West",K45="eu-west"),"EU-West", IF(OR(K45="US_East",K45="us-east",K45="US-East"),"US-East","Other")) -> EU-West | Q45: 30 | R45: 37 | S45: 89.91 | T45: 43.33 | U45: 96.54 | V45: 3312.5749 | W45: 2291.9192 | X45: =W45/V45 -> 0.6918845 | Y45: =IF(X45>1,"Over Budget","OK") -> OK | AA45: CloudProject_43 | AB45: 45058.856
A46: PRJ100044 | F46: 773 | G46: 1449.48 | H46: 30 | I46: 28 | J46: 2.53 | K46: US_East | L46: =IF(OR(K46="Europe-West",K46="EU_West",K46="eu-west"),"EU-West", IF(OR(K46="US_East",K46="us-east",K46="US-East"),"US-East","Other")) -> US-East | Q46: 40 | R46: 27 | S46: 100 | T46: 61.31 | U46: 91.51 | V46: 1795.9832 | W46: 1421.6025 | X46: =W46/V46 -> 0.79154552 | Y46: =IF(X46>1,"Over Budget","OK") -> OK | AA46: CloudProject_44 | AB46: 45734.626
A47: PRJ100045 | F47: 596 | G47: 1959.69 | H47: 0 | I47: 0 | J47: 24.94 | K47: us-east | L47: =IF(OR(K47="Europe-West",K47="EU_West",K47="eu-west"),"EU-West", IF(OR(K47="US_East",K47="us-east",K47="US-East"),"US-East","Other")) -> US-East | Q47: 10 | R47: 40 | S47: 53.89 | T47: 57.12 | U47: 83.66 | V47: 2619.8513 | W47: 2304.979 | X47: =W47/V47 -> 0.87981289 | Y47: =IF(X47>1,"Over Budget","OK") -> OK | AA47: CloudProject_45 | AB47: 45083.017
...

Sheet Visualisation

Sheet Data_Quality_Summary_Audit
A1: Dataset Overview | D1: Data Validity Checks
A3: Metric | B3: Result | D3: Check | E3: Result | F3: Status
A4: Total Rows (Excluding Header) | B4: 5000 | D4: Negative Usage_Cost | E4: =COUNTIF(Sheet1!G2:G5001,"<0") -> 0 | F4: =IF(E4=0,"No Issue","Issue Found") -> No Issue
A5: Duplicate Records | B5: 0 | D5: Negative Budget_Allocated | E5: =COUNTIF(Sheet1!U2:U5001,"<0") -> 0 | F5: No Issue
A6: Fully Empty Columns | B6: 9 | D6: Negative Budget_Consumed | E6: =COUNTIF(Sheet1!V2:V5001,"<0") -> 0 | F6: No Issue
A7: Partially Missing Columns | B7: 3 | D7: Reversed Start/End Dates | E7: =COUNTIF(Sheet1!M2:M5001,">"&Sheet1!N2:N5001) -> 0 | F7: No Issue
A8: Projects > 100% Budget | B8: 0.1 | D8: Budget_Consumed > Budget_Allocated | E8: 509 | F8: Over Budget Projects
A10: Missing Values Summary | D10: Descriptive Statistics
A12: Column | B12: Missing Count | C12: Status | D12: Metric | E12: Mean | F12: Median | G12: Min | H12: Max | I12: Std Dev
A13: Project_ID | B13: 0 | C13: No Missing | D13: Usage_Cost | E13: =AVERAGE(Sheet1!G2:G5001) -> 2033.955 | F13: =MEDIAN(Sheet1!G2:G5001) -> 1948.07 | G13: =MIN(Sheet1!G2:G5001) -> 1097.76 | H13: =MAX(Sheet1!G2:G5001) -> 13275.977 | I13: =_xlfn.STDEV.S(Sheet1!G2:G5001) -> 621.37684
A14: Environment | B14: 5000 | C14: Fully Empty | D14: Budget_Consumed | E14: =AVERAGE(Sheet1!W2:W5001) -> 2003.825 | F14: =MEDIAN(Sheet1!W2:W5001) -> 1936.6693 | G14: =MIN(Sheet1!W2:W5001) -> 917.76487 | H14: =MAX(Sheet1!W2:W5001) -> 5541.6626 | I14: =_xlfn.STDEV.P(Sheet1!W2:W5001) -> 501.9903
A15: Account_ID | B15: 5000 | C15: Fully Empty | D15: Budget_Utilization | E15: =AVERAGE(Sheet1!X2:X5001) -> 0.81280809 | F15: =MEDIAN(Sheet1!X2:X5001) -> 0.80344211 | G15: =MIN(Sheet1!X2:X5001) -> 0.54018179 | H15: =MAX(Sheet1!X2:X5001) -> 1.1889822 | I15: =_xlfn.STDEV.P(Sheet1!X2:X5001) -> 0.13423279
A16: Department | B16: 5000 | C16: Fully Empty | D16: Tagging_Completeness | E16: =AVERAGE(Sheet1!U2:U5001) -> 89.883321 | F16: =MEDIAN(Sheet1!U2:U5001) -> 89.975 | G16: =MIN(Sheet1!U2:U5001) -> 36.596753 | H16: =MAX(Sheet1!U2:U5001) -> 100 | I16: =_xlfn.STDEV.P(Sheet1!U2:U5001) -> 5.2029504
A17: Application | B17: 5000 | C17: Fully Empty | D17: Resource_Utilization_Percent | E17: =AVERAGE(Sheet1!S2:S5001) -> 69.690396 | F17: =MEDIAN(Sheet1!S2:S5001) -> 70.01 | G17: =MIN(Sheet1!S2:S5001) -> 16.833154 | H17: =MAX(Sheet1!S2:S5001) -> 100 | I17: =_xlfn.STDEV.S(Sheet1!S2:S5001) -> 14.891033
A18: Number_of_Servers | B18: 0 | C18: No Missing
A19: Usage_Cost | B19: 143 | C19: Partially Missing
A20: Incident_Tickets_Opened | B20: 0 | C20: No Missing | D20: Correlation Analysis
A21: Incident_Tickets_Closed | B21: 0 | C21: No Missing
A22: Avg_Resolution_Time_Hours | B22: 0 | C22: No Missing | D22: Metric 1 | E22: Metric 2 | F22: Correlation | G22: Interpretation
A23: Region | B23: 0 | C23: No Missing | D23: Usage_Cost | E23: Budget_Consumed | F23: =CORREL(Sheet1!G2:G5001, Sheet1!W2:W5001) -> 0.64027177 | G23: Moderate
A24: Cloud_Provider | B24: 5000 | C24: Fully Empty | D24: Budget_Consumed | E24: Budget_Utilization | F24: =CORREL(Sheet1!W2:W5001, Sheet1!X2:X5001) -> 0.31163018 | G24: Weak
A25: Project_Start_Date | B25: 5000 | C25: Fully Empty | D25: Usage_Cost | E25: Resource_Utilization_Percent | F25: =CORREL(Sheet1!G2:G5001, Sheet1!S2:S5001) -> -0.1123742 | G25: No meaningful relationship
A26: Project_End_Date | B26: 5000 | C26: Fully Empty | D26: Tagging_Completeness | E26: Resource_Utilization_Percent | F26: =CORREL(Sheet1!U2:U5001, Sheet1!S2:S5001) -> 0.040328763 | G26: Very Weak
A27: Compliance_Flag | B27: 5000 | C27: Fully Empty
A28: SLA_Breach_Count | B28: 0 | C28: No Missing
A29: Security_Alerts | B29: 0 | C29: No Missing
A30: Resource_Utilization_Percent | B30: 157 | C30: Partially Missing
A31: Reserved_Instance_Usage | B31: 0 | C31: No Missing
A32: Tagging_Completeness | B32: 136 | C32: Partially Missing
A33: Budget_Allocated | B33: 0 | C33: No Missing
A34: Budget_Consumed | B34: 0 | C34: No Missing
A35: Budget_Utilization | B35: 0 | C35: No Missing
A36: Over_Budget_Flag | B36: 0 | C36: No Missing
A37: Cost_Anomaly_Flag | B37: 5000 | C37: Fully Empty
A38: Project_Name | B38: 0 | C38: No Missing
A39: Date | B39: 0 | C39: No Missing
